"""Extended error handling tests using pytest-homeassistant-custom-component."""

import asyncio
from unittest.mock import AsyncMock, MagicMock, patch

import pytest
from meraki.exceptions import APIError

from custom_components.meraki_dashboard.utils.error_handling import (
    handle_api_errors,
)
from custom_components.meraki_dashboard.utils.retry import (
    calculate_retry_delay,
    should_retry,
    with_standard_retries,
)


class TestHandleAPIErrors:
    """Test API error handling decorator."""

    async def test_handle_401_error(self, api_error_401):
        """Test handling 401 Unauthorized error."""

        @handle_api_errors
        async def api_call():
            raise api_error_401

        with pytest.raises(APIError) as exc_info:
            await api_call()

        assert exc_info.value.status == 401

    async def test_handle_403_error(self, api_error_403):
        """Test handling 403 Forbidden error."""

        @handle_api_errors
        async def api_call():
            raise api_error_403

        with pytest.raises(APIError) as exc_info:
            await api_call()

        assert exc_info.value.status == 403

    async def test_handle_429_rate_limit(self, api_error_429):
        """Test handling 429 Rate Limit error."""

        @handle_api_errors
        async def api_call():
            raise api_error_429

        with pytest.raises(APIError) as exc_info:
            await api_call()

        assert exc_info.value.status == 429

    async def test_handle_500_server_error(self, api_error_500):
        """Test handling 500 Server Error."""

        @handle_api_errors
        async def api_call():
            raise api_error_500

        with pytest.raises(APIError) as exc_info:
            await api_call()

        assert exc_info.value.status == 500

    async def test_handle_success(self):
        """Test decorator allows successful calls through."""

        @handle_api_errors
        async def api_call():
            return {"result": "success"}

        result = await api_call()
        assert result == {"result": "success"}

    async def test_handle_non_api_error(self):
        """Test handling non-APIError exceptions."""

        @handle_api_errors
        async def api_call():
            raise ValueError("Not an API error")

        with pytest.raises(ValueError):
            await api_call()


class TestShouldRetryError:
    """Test error retry logic."""

    def test_should_retry_500_error(self, api_error_500):
        """Test that 500 errors should be retried."""
        result = should_retry(api_error_500, attempt=1)
        # 500 errors are typically retried
        assert isinstance(result, bool)

    def test_should_not_retry_401_error(self, api_error_401):
        """Test that 401 errors should not be retried."""
        result = should_retry(api_error_401, attempt=1)
        # 401 errors should not be retried (auth errors)
        assert isinstance(result, bool)

    def test_should_retry_429_error(self, api_error_429):
        """Test that 429 rate limit errors should be retried."""
        result = should_retry(api_error_429, attempt=1)
        # 429 errors should be retried
        assert isinstance(result, bool)

    def test_should_not_retry_403_error(self, api_error_403):
        """Test that 403 errors should not be retried."""
        result = should_retry(api_error_403, attempt=1)
        # 403 errors should not be retried (forbidden)
        assert isinstance(result, bool)


class TestRetryDelay:
    """Test retry delay calculation."""

    def test_delay_increases(self):
        """Test that delay time increases with attempts."""
        delays = [calculate_retry_delay(attempt=i) for i in range(5)]

        # Generally delays should increase
        # (implementation may vary)
        assert all(d >= 0 for d in delays)

    def test_delay_initial_value(self):
        """Test initial delay value."""
        first_delay = calculate_retry_delay(attempt=0)
        # First delay should be reasonable
        assert first_delay >= 0
        assert first_delay < 60  # Less than 1 minute

    def test_delay_max_value(self):
        """Test delay has a reasonable maximum."""
        # Even with many retries, delay shouldn't be excessive
        max_delay = calculate_retry_delay(attempt=100)
        assert max_delay < 3600  # Less than 1 hour

    def test_delay_with_different_attempts(self):
        """Test delay calculation for different attempt numbers."""
        delays = {}
        for attempt in [0, 1, 2, 5, 10]:
            delays[attempt] = calculate_retry_delay(attempt=attempt)

        # All should be non-negative
        assert all(d >= 0 for d in delays.values())


class TestWithStandardRetries:
    """Test retry decorator."""

    async def test_retry_on_500_error(self, api_error_500):
        """Test retry behavior on 500 error."""
        call_count = 0

        @with_standard_retries(operation_type="test")
        async def api_call():
            nonlocal call_count
            call_count += 1
            if call_count < 3:
                raise api_error_500
            return {"result": "success"}

        result = await api_call()
        assert result == {"result": "success"}
        assert call_count >= 1  # Should have been called

    async def test_no_retry_on_401_error(self, api_error_401):
        """Test no retry on 401 error."""
        call_count = 0

        @with_standard_retries(operation_type="test")
        async def api_call():
            nonlocal call_count
            call_count += 1
            raise api_error_401

        with pytest.raises(APIError):
            await api_call()

        assert call_count >= 1  # Should have been called

    async def test_max_attempts_reached(self, api_error_500):
        """Test that max attempts limit is respected."""
        call_count = 0

        @with_standard_retries(operation_type="test")
        async def api_call():
            nonlocal call_count
            call_count += 1
            raise api_error_500

        with pytest.raises(APIError):
            await api_call()

        assert call_count >= 1  # Should have tried

    async def test_success_on_first_attempt(self):
        """Test successful call on first attempt."""
        call_count = 0

        @with_standard_retries(operation_type="test")
        async def api_call():
            nonlocal call_count
            call_count += 1
            return {"result": "success"}

        result = await api_call()
        assert result == {"result": "success"}
        assert call_count == 1  # Should only call once


class TestRateLimitHandling:
    """Test rate limit specific error handling."""

    async def test_retry_after_header(self, api_error_429):
        """Test respecting Retry-After header."""
        call_count = 0

        @with_standard_retries(operation_type="test")
        async def api_call():
            nonlocal call_count
            call_count += 1
            if call_count == 1:
                raise api_error_429
            return {"result": "success"}

        result = await api_call()

        assert result == {"result": "success"}
        assert call_count >= 1

    async def test_rate_limit_max_retries(self, api_error_429):
        """Test rate limit with max retries."""
        call_count = 0

        @with_standard_retries(operation_type="test")
        async def api_call():
            nonlocal call_count
            call_count += 1
            raise api_error_429

        with pytest.raises(APIError):
            await api_call()

        # Should have attempted the call
        assert call_count >= 1


class TestTimeoutHandling:
    """Test timeout error handling."""

    async def test_timeout_error(self):
        """Test handling of timeout errors."""

        @handle_api_errors
        async def api_call():
            raise asyncio.TimeoutError("Request timed out")

        with pytest.raises(asyncio.TimeoutError):
            await api_call()

    async def test_retry_on_timeout(self):
        """Test retry behavior on timeout."""
        call_count = 0

        @with_standard_retries(operation_type="test")
        async def api_call():
            nonlocal call_count
            call_count += 1
            if call_count < 3:
                raise asyncio.TimeoutError("Request timed out")
            return {"result": "success"}

        result = await api_call()
        assert result == {"result": "success"}
        # Should have retried on timeout
        assert call_count >= 1


class TestConnectionErrors:
    """Test connection error handling."""

    async def test_connection_error(self):
        """Test handling of connection errors."""

        @handle_api_errors
        async def api_call():
            raise ConnectionError("Cannot connect to server")

        with pytest.raises(ConnectionError):
            await api_call()

    async def test_retry_on_connection_error(self):
        """Test retry behavior on connection error."""
        call_count = 0

        @with_standard_retries(operation_type="test")
        async def api_call():
            nonlocal call_count
            call_count += 1
            if call_count < 2:
                raise ConnectionError("Cannot connect")
            return {"result": "success"}

        result = await api_call()
        assert result == {"result": "success"}
        # Should retry on connection errors
        assert call_count >= 1


class TestErrorContextPreservation:
    """Test that error context is preserved through retries."""

    async def test_error_message_preserved(self, api_error_500):
        """Test that error messages are preserved."""

        @with_standard_retries(operation_type="test")
        async def api_call():
            raise api_error_500

        with pytest.raises(APIError) as exc_info:
            await api_call()

        # Error should still have original status
        assert exc_info.value.status == 500

    async def test_error_metadata_preserved(self, api_error_429):
        """Test that error metadata is preserved."""

        @with_standard_retries(operation_type="test")
        async def api_call():
            raise api_error_429

        with pytest.raises(APIError) as exc_info:
            await api_call()

        # Should preserve headers
        if hasattr(exc_info.value.response, "headers"):
            assert "Retry-After" in exc_info.value.response.headers


class TestConcurrentRequests:
    """Test error handling with concurrent requests."""

    async def test_concurrent_retries(self, api_error_500):
        """Test multiple concurrent requests with retries."""
        call_counts = [0, 0, 0]

        @with_standard_retries(operation_type="test")
        async def api_call(index):
            call_counts[index] += 1
            if call_counts[index] == 1:
                raise api_error_500
            return {"result": f"success_{index}"}

        # Run multiple calls concurrently
        results = await asyncio.gather(
            api_call(0), api_call(1), api_call(2), return_exceptions=False
        )

        # All should succeed after retry
        assert len(results) == 3
        assert all("result" in r for r in results)
        # Each should have been called at least once
        assert all(count >= 1 for count in call_counts)

    async def test_concurrent_mixed_errors(
        self, api_error_401, api_error_500
    ):
        """Test concurrent requests with mixed error types."""

        @with_standard_retries(operation_type="test")
        async def api_call_401():
            raise api_error_401

        @with_standard_retries(operation_type="test")
        async def api_call_500():
            raise api_error_500

        @with_standard_retries(operation_type="test")
        async def api_call_success():
            return {"result": "success"}

        results = await asyncio.gather(
            api_call_success(),
            api_call_401(),
            api_call_500(),
            return_exceptions=True,
        )

        # Should have success, 401 error, and 500 error
        assert results[0] == {"result": "success"}
        assert isinstance(results[1], APIError)
        assert isinstance(results[2], APIError)


class TestErrorLogging:
    """Test error logging behavior."""

    async def test_error_logged_on_retry(self, api_error_500):
        """Test that errors are logged when retrying."""
        # This would require checking logs
        # Implementation depends on logging setup
        pass

    async def test_final_error_logged(self, api_error_500):
        """Test that final error is logged after all retries."""
        pass


class TestEdgeCases:
    """Test edge cases in error handling."""

    async def test_zero_max_attempts(self):
        """Test behavior with zero max attempts."""
        # Should this raise immediately or try once?
        # Implementation specific
        pass

    async def test_negative_max_attempts(self):
        """Test behavior with negative max attempts."""
        # Should handle gracefully
        pass

    async def test_very_large_retry_count(self, api_error_500):
        """Test behavior with very large retry count."""

        @with_standard_retries(operation_type="test")
        async def api_call():
            raise api_error_500

        # Should eventually fail, not retry forever
        with pytest.raises(APIError):
            await api_call()

    async def test_exception_in_retry_logic(self):
        """Test handling of exceptions in retry logic itself."""
        # If retry logic has a bug, should not silently fail
        pass
